[2023-05-08T10:39:38.068+0000] {taskinstance.py:1171} INFO - Dependencies all met for <TaskInstance: crawl_dag.crawl_data manual__2023-05-08T10:39:35.595490+00:00 [queued]>
[2023-05-08T10:39:38.084+0000] {taskinstance.py:1171} INFO - Dependencies all met for <TaskInstance: crawl_dag.crawl_data manual__2023-05-08T10:39:35.595490+00:00 [queued]>
[2023-05-08T10:39:38.085+0000] {taskinstance.py:1368} INFO - 
--------------------------------------------------------------------------------
[2023-05-08T10:39:38.086+0000] {taskinstance.py:1369} INFO - Starting attempt 1 of 2
[2023-05-08T10:39:38.087+0000] {taskinstance.py:1370} INFO - 
--------------------------------------------------------------------------------
[2023-05-08T10:39:38.108+0000] {taskinstance.py:1389} INFO - Executing <Task(PythonOperator): crawl_data> on 2023-05-08 10:39:35.595490+00:00
[2023-05-08T10:39:38.114+0000] {standard_task_runner.py:52} INFO - Started process 641 to run task
[2023-05-08T10:39:38.117+0000] {standard_task_runner.py:79} INFO - Running: ['***', 'tasks', 'run', 'crawl_dag', 'crawl_data', 'manual__2023-05-08T10:39:35.595490+00:00', '--job-id', '9', '--raw', '--subdir', 'DAGS_FOLDER/test_dag_2.py', '--cfg-path', '/tmp/tmp6sdbhrxc', '--error-file', '/tmp/tmp4la_yb2e']
[2023-05-08T10:39:38.120+0000] {standard_task_runner.py:80} INFO - Job 9: Subtask crawl_data
[2023-05-08T10:39:38.197+0000] {task_command.py:371} INFO - Running <TaskInstance: crawl_dag.crawl_data manual__2023-05-08T10:39:35.595490+00:00 [running]> on host 42e8216d44a8
[2023-05-08T10:39:38.294+0000] {taskinstance.py:1583} INFO - Exporting the following env vars:
AIRFLOW_CTX_DAG_EMAIL=thanhnb@ftech.ai
AIRFLOW_CTX_DAG_OWNER=***
AIRFLOW_CTX_DAG_ID=crawl_dag
AIRFLOW_CTX_TASK_ID=crawl_data
AIRFLOW_CTX_EXECUTION_DATE=2023-05-08T10:39:35.595490+00:00
AIRFLOW_CTX_TRY_NUMBER=1
AIRFLOW_CTX_DAG_RUN_ID=manual__2023-05-08T10:39:35.595490+00:00
[2023-05-08T10:39:38.437+0000] {taskinstance.py:1902} ERROR - Task failed with exception
Traceback (most recent call last):
  File "/home/airflow/.local/lib/python3.7/site-packages/airflow/operators/python.py", line 171, in execute
    return_value = self.execute_callable()
  File "/home/airflow/.local/lib/python3.7/site-packages/airflow/operators/python.py", line 189, in execute_callable
    return self.python_callable(*self.op_args, **self.op_kwargs)
  File "/opt/airflow/dags/test_dag_2.py", line 25, in crawl_ck
    driver = webdriver.Chrome()
  File "/home/airflow/.local/lib/python3.7/site-packages/selenium/webdriver/chrome/webdriver.py", line 93, in __init__
    keep_alive,
  File "/home/airflow/.local/lib/python3.7/site-packages/selenium/webdriver/chromium/webdriver.py", line 112, in __init__
    options=options,
  File "/home/airflow/.local/lib/python3.7/site-packages/selenium/webdriver/remote/webdriver.py", line 286, in __init__
    self.start_session(capabilities, browser_profile)
  File "/home/airflow/.local/lib/python3.7/site-packages/selenium/webdriver/remote/webdriver.py", line 378, in start_session
    response = self.execute(Command.NEW_SESSION, parameters)
  File "/home/airflow/.local/lib/python3.7/site-packages/selenium/webdriver/remote/webdriver.py", line 440, in execute
    self.error_handler.check_response(response)
  File "/home/airflow/.local/lib/python3.7/site-packages/selenium/webdriver/remote/errorhandler.py", line 245, in check_response
    raise exception_class(message, screen, stacktrace)
selenium.common.exceptions.WebDriverException: Message: unknown error: Chrome failed to start: crashed.
  (unknown error: DevToolsActivePort file doesn't exist)
  (The process started from chrome location /usr/bin/google-chrome is no longer running, so ChromeDriver is assuming that Chrome has crashed.)
Stacktrace:
#0 0x55a0638ed133 <unknown>
#1 0x55a063621966 <unknown>
#2 0x55a06364b21a <unknown>
#3 0x55a06364707b <unknown>
#4 0x55a0636869ad <unknown>
#5 0x55a06368618f <unknown>
#6 0x55a06367d9a3 <unknown>
#7 0x55a06365246a <unknown>
#8 0x55a06365355e <unknown>
#9 0x55a0638accae <unknown>
#10 0x55a0638b08fe <unknown>
#11 0x55a0638b9f20 <unknown>
#12 0x55a0638b1923 <unknown>
#13 0x55a063884c0e <unknown>
#14 0x55a0638d4b08 <unknown>
#15 0x55a0638d4c97 <unknown>
#16 0x55a0638e5113 <unknown>
#17 0x7f54b237aea7 start_thread

[2023-05-08T10:39:38.460+0000] {taskinstance.py:1412} INFO - Marking task as UP_FOR_RETRY. dag_id=crawl_dag, task_id=crawl_data, execution_date=20230508T103935, start_date=20230508T103938, end_date=20230508T103938
[2023-05-08T10:39:38.479+0000] {warnings.py:110} WARNING - /home/***/.local/lib/python3.7/site-packages/***/utils/email.py:119: PendingDeprecationWarning: Fetching SMTP credentials from configuration variables will be deprecated in a future release. Please set credentials using a connection instead.
  send_mime_email(e_from=mail_from, e_to=recipients, mime_msg=msg, conn_id=conn_id, dryrun=dryrun)

[2023-05-08T10:39:38.480+0000] {configuration.py:562} WARNING - section/key [smtp/smtp_user] not found in config
[2023-05-08T10:39:38.481+0000] {email.py:228} INFO - Email alerting: attempt 1
[2023-05-08T10:39:38.487+0000] {configuration.py:562} WARNING - section/key [smtp/smtp_user] not found in config
[2023-05-08T10:39:38.487+0000] {email.py:228} INFO - Email alerting: attempt 1
[2023-05-08T10:39:38.489+0000] {taskinstance.py:1957} ERROR - Failed to send email to: ['thanhnb@ftech.ai']
Traceback (most recent call last):
  File "/home/airflow/.local/lib/python3.7/site-packages/airflow/models/taskinstance.py", line 1463, in _run_raw_task
    self._execute_task_with_callbacks(context, test_mode)
  File "/home/airflow/.local/lib/python3.7/site-packages/airflow/models/taskinstance.py", line 1610, in _execute_task_with_callbacks
    result = self._execute_task(context, task_orig)
  File "/home/airflow/.local/lib/python3.7/site-packages/airflow/models/taskinstance.py", line 1671, in _execute_task
    result = execute_callable(context=context)
  File "/home/airflow/.local/lib/python3.7/site-packages/airflow/operators/python.py", line 171, in execute
    return_value = self.execute_callable()
  File "/home/airflow/.local/lib/python3.7/site-packages/airflow/operators/python.py", line 189, in execute_callable
    return self.python_callable(*self.op_args, **self.op_kwargs)
  File "/opt/airflow/dags/test_dag_2.py", line 25, in crawl_ck
    driver = webdriver.Chrome()
  File "/home/airflow/.local/lib/python3.7/site-packages/selenium/webdriver/chrome/webdriver.py", line 93, in __init__
    keep_alive,
  File "/home/airflow/.local/lib/python3.7/site-packages/selenium/webdriver/chromium/webdriver.py", line 112, in __init__
    options=options,
  File "/home/airflow/.local/lib/python3.7/site-packages/selenium/webdriver/remote/webdriver.py", line 286, in __init__
    self.start_session(capabilities, browser_profile)
  File "/home/airflow/.local/lib/python3.7/site-packages/selenium/webdriver/remote/webdriver.py", line 378, in start_session
    response = self.execute(Command.NEW_SESSION, parameters)
  File "/home/airflow/.local/lib/python3.7/site-packages/selenium/webdriver/remote/webdriver.py", line 440, in execute
    self.error_handler.check_response(response)
  File "/home/airflow/.local/lib/python3.7/site-packages/selenium/webdriver/remote/errorhandler.py", line 245, in check_response
    raise exception_class(message, screen, stacktrace)
selenium.common.exceptions.WebDriverException: Message: unknown error: Chrome failed to start: crashed.
  (unknown error: DevToolsActivePort file doesn't exist)
  (The process started from chrome location /usr/bin/google-chrome is no longer running, so ChromeDriver is assuming that Chrome has crashed.)
Stacktrace:
#0 0x55a0638ed133 <unknown>
#1 0x55a063621966 <unknown>
#2 0x55a06364b21a <unknown>
#3 0x55a06364707b <unknown>
#4 0x55a0636869ad <unknown>
#5 0x55a06368618f <unknown>
#6 0x55a06367d9a3 <unknown>
#7 0x55a06365246a <unknown>
#8 0x55a06365355e <unknown>
#9 0x55a0638accae <unknown>
#10 0x55a0638b08fe <unknown>
#11 0x55a0638b9f20 <unknown>
#12 0x55a0638b1923 <unknown>
#13 0x55a063884c0e <unknown>
#14 0x55a0638d4b08 <unknown>
#15 0x55a0638d4c97 <unknown>
#16 0x55a0638e5113 <unknown>
#17 0x7f54b237aea7 start_thread


During handling of the above exception, another exception occurred:

Traceback (most recent call last):
  File "/home/airflow/.local/lib/python3.7/site-packages/airflow/models/taskinstance.py", line 2339, in email_alert
    send_email(task.email, subject, html_content)
  File "/home/airflow/.local/lib/python3.7/site-packages/airflow/utils/email.py", line 71, in send_email
    **kwargs,
  File "/home/airflow/.local/lib/python3.7/site-packages/airflow/utils/email.py", line 119, in send_email_smtp
    send_mime_email(e_from=mail_from, e_to=recipients, mime_msg=msg, conn_id=conn_id, dryrun=dryrun)
  File "/home/airflow/.local/lib/python3.7/site-packages/airflow/utils/email.py", line 230, in send_mime_email
    smtp_conn = _get_smtp_connection(smtp_host, smtp_port, smtp_timeout, smtp_ssl)
  File "/home/airflow/.local/lib/python3.7/site-packages/airflow/utils/email.py", line 264, in _get_smtp_connection
    else smtplib.SMTP(host=host, port=port, timeout=timeout)
  File "/usr/local/lib/python3.7/smtplib.py", line 251, in __init__
    (code, msg) = self.connect(host, port)
  File "/usr/local/lib/python3.7/smtplib.py", line 336, in connect
    self.sock = self._get_socket(host, port, self.timeout)
  File "/usr/local/lib/python3.7/smtplib.py", line 307, in _get_socket
    self.source_address)
  File "/usr/local/lib/python3.7/socket.py", line 728, in create_connection
    raise err
  File "/usr/local/lib/python3.7/socket.py", line 716, in create_connection
    sock.connect(sa)
OSError: [Errno 99] Cannot assign requested address

During handling of the above exception, another exception occurred:

Traceback (most recent call last):
  File "/home/airflow/.local/lib/python3.7/site-packages/airflow/models/taskinstance.py", line 1955, in handle_failure
    self.email_alert(error, task)
  File "/home/airflow/.local/lib/python3.7/site-packages/airflow/models/taskinstance.py", line 2341, in email_alert
    send_email(task.email, subject, html_content_err)
  File "/home/airflow/.local/lib/python3.7/site-packages/airflow/utils/email.py", line 71, in send_email
    **kwargs,
  File "/home/airflow/.local/lib/python3.7/site-packages/airflow/utils/email.py", line 119, in send_email_smtp
    send_mime_email(e_from=mail_from, e_to=recipients, mime_msg=msg, conn_id=conn_id, dryrun=dryrun)
  File "/home/airflow/.local/lib/python3.7/site-packages/airflow/utils/email.py", line 230, in send_mime_email
    smtp_conn = _get_smtp_connection(smtp_host, smtp_port, smtp_timeout, smtp_ssl)
  File "/home/airflow/.local/lib/python3.7/site-packages/airflow/utils/email.py", line 264, in _get_smtp_connection
    else smtplib.SMTP(host=host, port=port, timeout=timeout)
  File "/usr/local/lib/python3.7/smtplib.py", line 251, in __init__
    (code, msg) = self.connect(host, port)
  File "/usr/local/lib/python3.7/smtplib.py", line 336, in connect
    self.sock = self._get_socket(host, port, self.timeout)
  File "/usr/local/lib/python3.7/smtplib.py", line 307, in _get_socket
    self.source_address)
  File "/usr/local/lib/python3.7/socket.py", line 728, in create_connection
    raise err
  File "/usr/local/lib/python3.7/socket.py", line 716, in create_connection
    sock.connect(sa)
OSError: [Errno 99] Cannot assign requested address
[2023-05-08T10:39:38.512+0000] {standard_task_runner.py:97} ERROR - Failed to execute job 9 for task crawl_data (Message: unknown error: Chrome failed to start: crashed.
  (unknown error: DevToolsActivePort file doesn't exist)
  (The process started from chrome location /usr/bin/google-chrome is no longer running, so ChromeDriver is assuming that Chrome has crashed.)
Stacktrace:
#0 0x55a0638ed133 <unknown>
#1 0x55a063621966 <unknown>
#2 0x55a06364b21a <unknown>
#3 0x55a06364707b <unknown>
#4 0x55a0636869ad <unknown>
#5 0x55a06368618f <unknown>
#6 0x55a06367d9a3 <unknown>
#7 0x55a06365246a <unknown>
#8 0x55a06365355e <unknown>
#9 0x55a0638accae <unknown>
#10 0x55a0638b08fe <unknown>
#11 0x55a0638b9f20 <unknown>
#12 0x55a0638b1923 <unknown>
#13 0x55a063884c0e <unknown>
#14 0x55a0638d4b08 <unknown>
#15 0x55a0638d4c97 <unknown>
#16 0x55a0638e5113 <unknown>
#17 0x7f54b237aea7 start_thread
; 641)
[2023-05-08T10:39:38.533+0000] {local_task_job.py:156} INFO - Task exited with return code 1
[2023-05-08T10:39:38.567+0000] {local_task_job.py:279} INFO - 0 downstream tasks scheduled from follow-on schedule check
